Workbook

Sheet Scoring Sheet
B1: Usage Questions [scored] | V1: Knowledge Questions [scored] | AG1: Prompting Questions [scored] | AT1: Overall Score | AW1: Behavioral Questions [unscored] | BS1: Demographic Questions [unscored]
AT2: Prompting | AV2: 2
A3: Weight | C3: 0.5 | F3: 1.5 | H3: 1 | J3: 1 | O3: 2 | T3: 4 | W3: 2 | Y3: 2 | AA3: 2 | AC3: 2 | AE3: 2 | AF3: =sum(V3:AE3) -> 10 | AH3: 1.5 | AM3: 3.5 | AR3: 5 | AT3: Knowledge | AV3: 1
A4: Potential Points | C4: 1 | F4: 1 | H4: 1 | J4: 1 | O4: 1 | T4: 1 | W4: 1 | Y4: 1 | AA4: 1 | AC4: 1 | AE4: 1 | AH4: 1 | AM4: 1 | AR4: 1 | AT4: Usage | AV4: 2
K5: {{QUESTION 5 RESPONSE}} | P5: {{QUESTION 6 RESPONSE}} | AI5: {{QUESTION 13 RESPONSE}} | AN5: {{QUESTION 14 RESPONSE}}
A6: ='Raw Data'!$A2 -> Participant Identifier | B6: ='Raw Data'!$K2 -> How often do you use AI tools for work-related tasks? | C6: SCORE | D6: ='Raw Data'!$L2 -> Which of the following best describes how you typically use AI at work? Select all that apply. | E6: SCORE | F6: SCORE (out of 1) | G6: ='Raw Data'!$M2 -> Which best describes your AI usage patterns at work? | H6: SCORE | I6: ='Raw Data'!$N2 -> You need to create a monthly performance summary. How would you use AI for this task? | J6: SCORE | K6: ='Raw Data'!O2 -> You have one week to create an important presentation for senior stakeholders on an unfamiliar topic. How would you use AI in this process? If you wouldn't use AI, please state that. | L6: TEXT: You have one week to create an important presentation for senior stakeholders on an unfamiliar topic. How would you use AI in this process? If you wouldn't use AI, please state that. | M6: TEMPLATE: You have one week to create an important presentation for senior stakeholders on an unfamiliar topic. How would you use AI in this process? If you wouldn't use AI, please state that. | N6: SCORE | O6: SCORE (out of 1) | P6: ='Raw Data'!$P2 -> What is the most useful or valuable way you are using AI in your work? | Q6: TEXT: What is the most useful or valuable way you are using AI in your work? | R6: TEMPLATE: What is the most useful or valuable way you are using AI in your work? | S6: SCORE | T6: SCORE (out of 1) | U6: OVERALL SCORE (out of 10) | V6: ='Raw Data'!$Q2 -> Which task would current AI tools (like ChatGPT, Copilot, or Gemini) handle most effectively? | W6: SCORE | X6: ='Raw Data'!$R2 -> Which of the following are the main risks of using current LLMs? Select all that apply. | Y6: SCORE | Z6: ='Raw Data'!$S2 -> How can you best protect sensitive information when using AI tools? Select all that apply. | AA6: SCORE | AB6: ='Raw Data'!T2 -> How often do you verify or fact-check AI-generated content before finalizing or sharing it? | AC6: SCORE | AD6: ='Raw Data'!$U2 -> When fact-checking AI-generated content, which approaches would be helpful? Select all that apply. | AE6: SCORE | AF6: OVERALL SCORE (out of 10) | AG6: ='Raw Data'!$V2 -> When you use AI, how often do you refine or iterate on your prompts to improve the output? | AH6: SCORE | AI6: ='Raw Data'!$W2 -> DRILL 1: Imagine you are preparing for a work meeting to discuss a new initiative or proposal. Write a prompt asking AI to help you prepare for this meeting. | AJ6: TEXT: DRILL 1: Imagine you are preparing for a work meeting to discuss a new initiative or proposal. Write a prompt asking AI to help you prepare for this meeting. | AK6: TEMPLATE: DRILL 1: Imagine you are preparing for a work meeting to discuss a new initiative or proposal. Write a prompt asking AI to help you prepare for this meeting. | AL6: SCORE | AM6: SCORE (out of 1) | AN6: ='Raw Data'!$X2 -> DRILL 2: Your team frequently researches competitors' products, pricing, and positioning. You want to create a Custom GPT (or Copilot Agent/Google Gem) for this task. Write instructions for this custom AI tool that would help team members gather competitive intelligence consistently. | AO6: TEXT: DRILL 2: Your team frequently researches competitors' products, pricing, and positioning. You want to create a Custom GPT (or Copilot Agent/Google Gem) for this task. Write instructions for this custom AI tool that would help team members gather competitive intelligence consistently. | AP6: TEMPLATE: DRILL 2: Your team frequently researches competitors' products, pricing, and positioning. You want to create a Custom GPT (or Copilot Agent/Google Gem) for this task. Write instructions for this custom AI tool that would help team members gather competitive intelligence consistently. | AQ6: SCORE | AR6: SCORE (out of 1) | AS6: OVERALL SCORE (out of 10) | AT6: OVERALL SCORE (out of 50) | AV6: Rating | AW6: ='Raw Data'!Y2 -> Which LLMs are you currently using? Select all that apply. | AX6: ='Raw Data'!Z2 -> Do you personally pay for access to any of these AI tools? | AY6: =#REF! -> #REF! | AZ6: =#REF! -> #REF! | BA6: =#REF! -> #REF! | BB6: =#REF! -> #REF! | BC6: =#REF! -> #REF! | BD6: =#REF! -> #REF! | BE6: =#REF! -> #REF! | BF6: =#REF! -> #REF! | ... BQ6: =#REF! -> #REF! | BR6: ='Raw Data'!C2 -> Which of the following best describes your current employment status? | BS6: ='Raw Data'!D2 -> What industry best describes where you currently work? | BT6: ='Raw Data'!E2 -> What function best describes your current role? | BU6: ='Raw Data'!F2 -> Which of the following best describes your current job level within your organization? | BV6: ='Raw Data'!G2 -> How many employees work at your company? | BW6: ='Raw Data'!H2 -> Where do you currently reside? | BX6: ='Raw Data'!I2 -> What is your current age? | BY6: ='Raw Data'!J2 -> What is your gender identity?
A7: ='Raw Data'!$A3 -> 1 | B7: ='Raw Data'!$K3 -> Weekly | C7: =if($B7="Never or rarely",0,if($B7="A few times a month",0.25,if($B7="Weekly",0.5,if($B7="Several times a week",0.75,if($B7="Daily",1))))) -> 0.5 | D7: ='Raw Data'!$L3 -> Editing or improving text I’ve already written (emails, documents, presentations), Analyzing data or documents to extract insights or summaries | E7: =if(isnumber(search("I don't use AI for work",$D7)),0,if(or(isnumber(search("Vibe Coding",$D7)),isnumber(search("custom prompts",$D7))),3,if(or(isnumber(search("brainstorming ideas",$D7)),isnumber(search("analyzing data",$D7)),isnumber(search("Creating first drafts",$D7))),2,1))) -> 2 | F7: =$E7/3 -> 0.66666667 | G7: ='Raw Data'!M3 -> I create fresh prompts each time I use AI | H7: =if($G7="I don't use AI for work",0,if($G7="I create fresh prompts each time I use AI",0.25,if($G7="I maintain a library of prompts that I reuse frequently",0.5,if($G7="I've build custom AI tools (CustomGPTs, Copilot Agents, Google Gems, Claude Projects) for repetitive tasks",0.75,if($G7="I've created workflows that connect AI with other systems (Slack, Salesforce, email) using integrations or code",1))))) -> 0.25 | I7: ='Raw Data'!$N3 -> Use AI to help analyze each data source, then compile results manually | J7: =if($I7="Ask AI to write the summary after you've analyzed all the data",0.33,if($I7="Use AI to help analyze each data source, then compile results manually",0.67,if($I7="Create a systematic process where AI handles data analysis and summary generation consistently",1,if($I7="I wouldn’t use AI for this task",0)))) -> 0.67 | K7: ='Raw Data'!$O3 -> I would first prompt the AI with information about the assignment, who it is for, who they are acting as, what topic to research, what to include and what not to include to start with. Then I would refine the prompts by asking new questions, until we arrive at a good version. Then I would check my work, and potentially craft in my own words/tone. | L7: I would first prompt the AI with information about the assignment, who it is for, who they are acting as, what topic to research, what to include and what not to include to start with. Then I would refine the prompts by asking new questions, until we arrive at a good version. Then I would check my work, and potentially craft in my own words/tone. | M7: =substitute('Prompt Template'!$A$2,$K$5,$L7) -> You are an expert evaluator of AI strategic thinking and workflow integration. Your goal is to evaluate how effectively survey respondents demonstrate strategic AI application based on their response to the question: “You have one week to create an important presentation for senior stakeholders on an unfamiliar topic. How would you use AI in this process?” Evaluate each response holistically across three key areas: Workflow Integration: Effective responses demonstrate systematic thinking by identifying multiple stages of the presentation process where AI can add value (research, analysis, content creation, structure, review, etc.). They show understanding that complex projects benefit from AI integration at various points rather than just using AI for one isolated task. Strategic Application: Strong responses show context-aware AI usage that specifically addresses the unique challenges of this scenario — leveraging AI to quickly understand an unfamiliar topic, tailoring content for senior stakeholders, and managing time constraints effectively. They go beyond generic AI applications to show thoughtful consideration of the specific requirements. Practical Execution: Quality responses demonstrate concrete understanding of how AI tools actually work by providing specific, actionable approaches rather than vague descriptions. They show familiarity with AI capabilities and limitations, and describe realistic implementation steps. Scoring Guidelines Score 3 — Strong strategic thinking • Demonstrates comprehensive AI integration across most or all key workflow stages (e.g., research, structure, content creation, context tailoring for senior stakeholders, review), combined with clear scenario awareness and practical execution. • Responses do not need to mention every single stage explicitly; concise or list-style answers can still score a 3 if they show a strategically complete, end-to-end approach that addresses the scenario’s unique challenges (unfamiliar topic, senior stakeholders, tight timelines). • Omitting one stage (e.g., review) does not disqualify a response if the overall strategy is robust and well-adapted. • Both structured and concise list-style responses are valid. Examples: • “Research topic comprehensively, analyze stakeholder needs, create presentation framework, develop content, review for clarity.” • “Use AI throughout the process — from initial research to final presentation polish — focusing on what senior stakeholders care about most.” • “I would use AI to research the topic, understand key stakeholder concerns, create a logical flow, and draft compelling content for senior leadership within the time constraint.” • “Scan unfamiliar topic, outline slides, tailor framing for executives, draft key content, fact-check and polish.” (Concise list-style example demonstrating full coverage) • “Research unfamiliar topic, structure the deck, tailor for executives, draft content.” (Covers most strategic stages, omits review but is still strategically comprehensive) Score 2 — Moderate strategic thinking • Demonstrates partial but not comprehensive coverage of the key strategic dimensions. • Typically covers two to three workflow stages (e.g., structure + content + some context) but omits one or more major elements such as research, scenario adaptation, or review. • May show good workflow integration but limited scenario context, or vice versa. • Responses may be clear and practical but reflect a mid-level strategic approach rather than end-to-end planning. Examples: • “Use AI to quickly understand the topic, then create an outline and draft the presentation content.” • “Research phase, analysis phase, content creation phase, review phase.” • “Use AI to help research industry trends and create slides tailored for executives.” • “Draft speaker notes, executive framing, summarize key sources.” (Covers content, some research, and context but lacks structure/review) • “10 slide structure, add citations, executive framing.” (Structure, review, context but no research/content creation) Score 1 — Limited strategic thinking • Shows basic or single AI application with little reference to workflow complexity or scenario context. • Generic AI usage that could apply to any presentation task. Examples: • “Use AI to research the topic and create slides.” • “ChatGPT for research, help with structure.” • “Research, writing, editing.” • “Ask AI to help me understand the topic.” Score 0 — No relevant response • No answer, states they wouldn’t use AI, or provides irrelevant content. Special Guidance on Format and Brevity • Do not penalize for response format or brevity. • Evaluate list-style or terse responses based on substance, not phrasing. • A concise response that clearly addresses all key strategic dimensions can score a 3. • Responses that address only part of the workflow or omit key scenario considerations should score a 2, even if clearly written. • Brevity alone should not lower a score. Output: For your response, ONLY output the single score (0–3). Do not include any explanation. Here is the user’s input: <user_input>I would first prompt the AI with information about the assignment, who it is for, who they are acting as, what topic to research, what to include and what not to include to start with. Then I would refine the prompts by asking new questions, until we arrive at a good version. Then I would check my work, and potentially craft in my own words/tone.</user_input> | N7: {=index('Response Scoring'!$C:$C,match($A7,'Response Scoring'!$A:$A,0))} -> 2 | O7: =$N7/3 -> 0.66666667 | P7: ='Raw Data'!$P3 -> In my work, gathering my one on one meeting notes into a summary overview of accomplishments and challenges. | Q7: In my work, gathering my one on one meeting notes into a summary overview of accomplishments and challenges. | R7: =substitute('Prompt Template'!$B$2,$P$5,$Q7) -> You are an expert evaluator of practical AI value creation in work contexts. Your goal is to evaluate how effectively survey respondents demonstrate valuable AI usage based on their response to the question: ‘What is the most useful or valuable way you are using AI in your work?’ Valuable AI usage enables higher speed and/or quality work outputs with measurable impact on workflow pain points or business objectives. Strong responses demonstrate AI integration that transforms how core work gets done, rather than providing minor convenience. Score 3 — Workflow Redesign / Integrated Use (Human-in-the-Loop or Automated) Definition: Demonstrates strategic, repeatable AI integration that has redesigned or materially enhanced how the respondent performs a core part of their job. AI is consistently embedded in their workflow, creates new capabilities, or systematically improves downstream outputs or decisions. Transformation may involve automation or a human-in-the-loop redesign. Transformation requires more than saving time on peripheral tasks. The AI use must alter how a core deliverable is created, reviewed, or decided on — not just replace small administrative tasks within it. Time savings are only valid when they result from a redesigned or automated workflow step that affects downstream outputs or team decision-making. Observable Signals (any two or more): • Defined trigger or cadence (e.g., “after every client call,” “weekly review,” or implied repetition such as “each week,” “after calls,” or “whenever new data is ready”). • Template, checklist, or structured prompt used consistently. • AI output feeds directly into another step or tool (e.g., CRM, backlog, report). • AI introduces a new step, quality gate, or sequencing change. • AI automation replaces a manual stage and enables higher-value analytical or decision-making work. • Concise responses still qualify if they clearly imply repeatable, embedded use. Contrast Examples: Meeting Notes → Follow-up • (3) “After each client call, I run a prompt that tags actions by owner and priority, then imports them into our tracker.” • (2) “After calls, I paste notes into AI to group actions by owner and due date.” • (1) “I use AI to summarize meeting notes.” Customer Feedback → Insights • (3) “Each week, AI clusters customer comments, maps them to product areas, and ranks issues I review for roadmap planning.” • (2) “AI helps cluster customer comments into themes for my monthly report.” • (1) “I ask AI to summarize customer feedback.” Data Analysis / SQL • (3) “AI generates and validates queries, produces comparison tables, and highlights anomalies I review in reports.” • (2) “AI drafts SQL queries and interprets results faster than manual work.” • (1) “AI explains SQL when I’m stuck.” Proposal / Report Writing • (3) “I use a repeatable AI template that turns briefs into full drafts with rationale and risks sections, which I refine for delivery.” • (2) “AI drafts first sections of my proposals based on my outline.” • (1) “AI helps me improve grammar and phrasing.” Competitive Research • (3) “AI normalizes competitor data, flags gaps, and generates a positioning summary for our quarterly review.” • (2) “AI extracts pricing and features into a summary table before I write my report.” • (1) “AI summarizes competitor websites.” Score 2 — Process Enhancement / Embedded Use Definition: Shows repeatable, meaningful AI use within an existing process that improves speed, quality, or consistency. AI use is consistent and relevant to core responsibilities, but the workflow design and logic remain the same. May include structured use for efficiency, but does not fundamentally change how deliverables are produced or how information flows. Observable Signals (any one): • Clear efficiency, clarity, or organization benefit. • Consistent use within a step of a recurring workflow. • Described as part of normal work, not one-off. • Partial structure or templates used manually. Examples: • “I use AI to organize survey responses and find key themes before my analysis.” • “AI drafts report sections to help me start faster.” • “I use AI to group meeting notes by owner for easier follow-up.” • “AI summarizes recurring reports or data updates to save time, but outputs are reviewed or reformatted manually.” Score 1 — Task Assistance / Surface-Level Use Definition: Describes episodic or one-step assistance focused on convenience or small efficiency gains. AI is not embedded in a structured workflow or used consistently. Includes short, isolated tasks that do not influence how other work is performed. Observable Signals: • Task-specific or one-off. • No cadence, handoff, or reuse. • Focused on formatting, writing, or explanation. • Peripheral use — does not alter how a core deliverable or process is executed. Examples: • “I use AI to fix grammar or reword emails.” • “AI helps me write Excel formulas or explain code.” • “I use AI to summarize meeting notes.” • “AI drafts short internal updates so I can focus elsewhere.” Score 0 — No or Irrelevant Use Definition: No evidence of AI use in a work context or explicitly states they do not use AI. Example: • “I don’t use AI in my work.” Evaluator Checklist When scoring, ignore writing quality and phrasing. Look for evidence of process depth: • Defined trigger or cadence? (explicit or implied) • Repeatable prompt, checklist, or playbook? • AI output feeding another step or tool? • Workflow sequence or ownership changed? • New capability or quality gate introduced? • When evaluating time savings, consider whether the AI use alters how a core deliverable is produced or simply removes a peripheral or administrative step. • Does the AI output directly support a core deliverable (e.g., reports, analysis, client output)? • Cohesion check: Are the tasks connected within a single workflow or purpose? • If the response lists multiple unrelated activities (e.g., “draft emails, brainstorm ideas, summarize reports”), treat it as multiple isolated uses and score at the lower level. Heuristic: • 3 = Embedded + ≥ 2 signals + cohesive workflow or clear transformation of core deliverable • 2 = Embedded + 0–1 signal + cohesive workflow, limited transformation • 1 = Isolated or peripheral task use • 0 = None Scoring Instruction: For your response, ONLY output the single score (0–3). Do not include any explanation. Here is the user’s input: <user_input>In my work, gathering my one on one meeting notes into a summary overview of accomplishments and challenges.</user_input> | S7: {=index('Response Scoring'!$E:$E,match($A7,'Response Scoring'!$A:$A,0))} -> 2 | T7: =$S7/3 -> 0.66666667 | U7: =sumproduct($B7:$T7,$B$4:$T$4) -> 3.42 | V7: ='Raw Data'!$Q3 -> Analyzing presentation slides to evaluate both the visual design and written content for consistency | W7: =if($V7="Analyzing presentation slides to evaluate both the visual design and written content for consistency",1,0) -> 1 | X7: ='Raw Data'!$R3 -> Hallucinations (generating false or misleading information), Biases in answers, Data privacy concerns when information is shared with an LLM, Vulnerability to manipulation by bad actors | Y7: =if(isnumber(search("Hallucinations",$X7)),0.25)+if(isnumber(search("Biases in answers",$X7)),0.25,0)+if(isnumber(search("Data privacy concerns",$X7)),0.25)+if(isnumber(search("Vulnerability",$X7)),0.25) -> 1 | Z7: ='Raw Data'!$S3 -> Verify that the AI tool has SSL/HTTPS encryption before using it, Only share information that you would be comfortable sharing internally with a colleague, Anonymize information by removing identifying details, Use secure company instances or enterprise plans when available | AA7: =if(or(isnumber(search("Avoid using AI tools",$Z7)),isnumber(search("Verify that the AI tool",$Z7))),0,(if(isnumber(SEARCH("Anonymize information",$Z7)),0.5)+if(isnumber(search("Use secure company instances",$Z7)),0.5))) -> 0 | AB7: ='Raw Data'!$T3 -> Always: I routinely cross-check AI outputs with reliable sources | AC7: =if($AB7="Never: I typically trust the output as is",0,if($AB7="Rarely: I only verify if something doesn't sound right",0.33,if($AB7="Sometimes: I do a quick check against known data or references",0.67,if($AB7="Always: I routinely cross-check AI outputs with reliable sources",1)))) -> 1 | AD7: ='Raw Data'!$U3 -> Cross-reference key claims with reliable external sources, Verify any calculations or data analysis independently | AE7: =if(or(isnumber(search("Check if the response uses confident language",$AD7)),isnumber(search("Look for professional formatting",$AD7))),0,(if(isnumber(search("Use a different AI tool",$AD7)),0.25)+if(isnumber(search("Cross-reference key claims",$AD7)),0.25)+if(isnumber(search("Verify any calculations",$AD7)),0.25)+if(isnumber(search("Ask the same AI tool",$AD7)),0.25))) -> 0.5 | AF7: =sumproduct($V7:$AE7,$V$3:$AE$3) -> 7 | AG7: ='Raw Data'!$V3 -> Sometimes: I iterate 2–3 times to reach a good result | AH7: =if($AG7="Never: I usually just ask once and accept the first response",0,if($AG7="Rarely: I only tweak the prompt if something feels obviously off",0.33,if($AG7="Sometimes: I iterate 2–3 times to reach a good result",0.67,if($AG7="Frequently: I systematically refine prompts until I’m satisfied",1)))) -> 0.67 | AI7: ='Raw Data'!$W3 -> You are a director of applications at a university, we are going into a brainstorming session about new ways to improve security for our remote learning students, can you provide 10 best practices that could be readily implement to improve security. Include both technological and human examples in your response. | AJ7: You are a director of applications at a university, we are going into a brainstorming session about new ways to improve security for our remote learning students, can you provide 10 best practices that could be readily implement to improve security. Include both technological and human examples in your response. | AK7: =substitute('Prompt Template'!$C$2,$AI$5,$AJ7) -> You are an expert prompt engineer. Your goal is to evaluate the effectiveness of the prompt below. Less effective prompts are too vague, open-ended, and do not give clear instructions. More effective prompts provide background, clear instructions, and are well structured. Since you are tasked with evaluating true effectiveness of the prompt, you can give scores of 1. This is for an AI Readiness Survey that will assess individuals' proficiency when using AI. <task>Write a prompt asking AI to help you prepare for a work meeting to discuss a new initiative or proposal</task> <prompt>You are a director of applications at a university, we are going into a brainstorming session about new ways to improve security for our remote learning students, can you provide 10 best practices that could be readily implement to improve security. Include both technological and human examples in your response.</prompt> A score of 1 prompt example: "Help me prepare for my work meeting" Rate the effectiveness on a scale of 1-5. Only respond with a single number from 1-5. If the person states they do not know how to prompt or their prompt isn't relevant to the task, give them a 0. Use the following criteria: Clarity and Specificity: A good prompt should be clear, specific, and focused. It should provide enough context and detail to guide the AI towards generating a relevant and useful response. Vague, open-ended, or ambiguous prompts make it difficult for the AI to understand the user's intent and can lead to generic or irrelevant outputs. Completeness and Sufficiency: An effective prompt should include all the necessary information and requirements to enable the AI to complete the requested task or answer the question thoroughly. It should anticipate what details the AI might need and proactively provide them. Incomplete prompts that leave out critical facts or constraints will likely result in suboptimal responses that fail to fully address the user's needs. Structure and Organization: A well-crafted prompt should be logically structured and organized. It should break down complex requests into clear steps or components, making it easier for the AI to process and respond to each part systematically. Using formatting techniques like bullet points, numbering, or sectioning can help improve the prompt's clarity and readability. Conciseness and Precision: While a good prompt should be detailed and informative, it should also strive to be as concise and precise as possible. Overly wordy or rambling prompts can obscure the key points and make it harder for the AI to identify the essential requirements. An effective prompt finds the right balance between providing necessary context and avoiding extraneous or redundant information. Here is the user's input: <user_input>You are a director of applications at a university, we are going into a brainstorming session about new ways to improve security for our remote learning students, can you provide 10 best practices that could be readily implement to improve security. Include both technological and human examples in your response.</user_input> | AL7: {=index('Response Scoring'!$G:$G,match($A7,'Response Scoring'!$A:$A,0))} -> 4 | AM7: =$AL7/5 -> 0.8 | AN7: ='Raw Data'!$X3 -> I don't know how to create a custom AI instructions. | AO7: I don't know how to create a custom AI instructions. | AP7: =substitute('Prompt Template'!$D$2,$AN$5,$AO7) -> You are an expert evaluator of AI instruction design and CustomGPT configuration. Your goal is to evaluate how effectively a respondent demonstrates their ability to write high-quality AI instructions — the kind used to configure tools like CustomGPTs, Copilot Agents, or Google Gems. The test question asks respondents to: ‘Write instructions for a Custom GPT that would help team members gather competitive intelligence consistently.’ This scenario is used only as a familiar example. Do not evaluate their knowledge of competitive analysis — only the clarity, structure, and effectiveness of their AI instruction design. The competitive intelligence context is a stand-in for any business task. Scoring Overview Rate each response on a scale of 0–5. • 5 = System-ready, strong demonstration of instruction design skill. • 0 = Irrelevant or no response. Focus on instructional quality, not topic expertise or formatting aesthetics. Evaluation Dimensions 1. Structural Design Effective instructions clearly define the inputs, process/steps, and outputs. They show logical sequencing (e.g., research → organize → summarize) and reflect understanding of how AI interprets procedural tasks. 2. Instructional Precision Steps and directives are specific, actionable, and testable by an AI. Avoids vague terms like “analyze competitors” without specifying how to do so or what output is expected. 3. Boundary and Role Definition Strong instructions establish clear context for the AI — defining its role, scope, and constraints. They guide what to include/exclude and how to handle ambiguity or conflicting data. 4. Reusability and Scalability Good instructions can be reused consistently by others. They define consistent formatting, data structures, or repeatable logic that ensures stable results across users or scenarios. 5. Outcome Alignment The best instructions would realistically result in a functioning CustomGPT that performs the intended task accurately and consistently. Weak ones would produce inconsistent or low-quality behavior. Scoring Guidelines Score 5 – System-Ready • Instructions could be pasted directly into a CustomGPT/Copilot and perform effectively. • They demonstrate full system readiness — meaning the AI could execute the intended behavior repeatedly and autonomously, without additional clarification. • Includes: • Defined role and purpose (who/what the AI is). • Clear inputs (what information or user query it receives). • Explicit steps/process (how the AI should perform the task). • Defined outputs (format, tone, or structure of response). • Constraints/quality controls (rules, caveats, or handling instructions). • Demonstrates awareness of how to build a reusable, consistent AI behavior. Example 1: “Role: Competitive Intelligence Assistant. Purpose: Gather structured competitor data from reliable sources. Inputs: Company/product names. Process: 1) Identify top 5 competitors, 2) Extract features/pricing, 3) Summarize differences in a table. Output: Comparative matrix. Guardrails: Only use credible, verifiable sources.” Example 2 (Natural-Language Equivalent): “This CustomGPT should act as our internal research analyst. When given a company or product name, it identifies credible sources like official websites, press releases, and reviews. It compares product features, pricing, and messaging across competitors and summarizes the results in a consistent table and a short written overview with citations. The report should flag any information that seems outdated or unverified and maintain a uniform format for reuse across projects.” Note: Responses may use either explicit headings (Role/Inputs/Process/Output) or fluent natural language. Both are valid if they include equivalent components and could realistically produce consistent, reusable results. Score 4 – Strong but Missing Refinements • Structured and actionable; includes most components (e.g., steps, outputs, and some constraints). • Missing minor refinements such as input specificity, error handling, or reusability mechanisms. • AI could perform the task, but inconsistently. Example 1: “Gather information on competitors’ products, features, and pricing. Summarize in a table. Cite reliable sources.” (Functional but missing full structure or clear constraints.) Example 2: “Create a CustomGPT that collects information from competitor websites, reviews, and announcements. Summarize pricing, features, and positioning in a table, then highlight new updates. Include dates and brief notes on source credibility.” (Strong structure, but lacks clear inputs and reusability framing.) Score 3 – Structured but Shallow • Provides a reasonable outline or list of tasks but lacks cohesion or precision. • Mentions the goal but misses how to operationalize it in a repeatable, system-friendly way. • AI would need to infer too much to work reliably. Example 1: “Research competitors and summarize key findings about pricing and positioning.” (Has intent but lacks sequencing or defined outputs.) Example 2: “The GPT should find information about our competitors’ pricing and products, summarize what’s different, and give a short write-up each week.” (Clear intent, but underspecified logic — reads more like a to-do list than executable instructions.) Score 2 – Fragmented or Vague • Mentions competitive research but provides minimal or disconnected guidance. • Steps are generic, unsequenced, or too ambiguous to drive consistent AI behavior. Example elements: “Look up competitors and gather details.” “Find competitor info and summarize.” (Too vague to translate into functioning instructions.) Score 1 – Minimal or Misunderstood • Shows fundamental misunderstanding of AI instruction design. • Generic, incomplete, or irrelevant content that couldn’t guide an AI system at all. Example elements: “Just tell GPT to look up competitors.” “I’d ask it to find info about other companies.” “Use ChatGPT to do competitive research for us.” “Help me understand what our competitors do better.” “Search online for competitor products and summarize.” (Shows surface-level familiarity with AI but no system thinking.) Score 0 – No Response or Irrelevant • Empty, “I don’t know,” or unrelated answer. Example elements: “Not sure what to put here.” “I don’t use GPT for that.” “I’d rather do that myself.” “No idea how to write that.” (Shows confusion or complete lack of task understanding.) Evaluator Checklist When scoring, focus on functional design quality, not formatting or topic expertise. Ask yourself: • Does the response clearly define the AI’s role, inputs, process, and outputs? • Are instructions specific, sequenced, and testable? • Do they include boundaries or quality controls? • Could the AI perform the task consistently and autonomously if these instructions were used? • Is the response written at a configuration level (system prompt) rather than a one-off user command? Heuristic: • 5 = Fully structured, system-ready, reusable. • 4 = Strong, nearly system-ready, missing refinements. • 3 = Structured but shallow. • 2 = Fragmented or vague. • 1 = Minimal or misunderstood. • 0 = None/irrelevant. Scoring Instruction: For your response, ONLY output the single score (0–5). Do not include any explanation. Here is the user’s input: <user_input>I don't know how to create a custom AI instructions.</user_input> | AQ7: {=index('Response Scoring'!$I:$I,match($A7,'Response Scoring'!$A:$A,0))} -> 0 | AR7: =$AQ7/5 -> 0 | AS7: =sumproduct($AG7:$AR7,$AG$3:$AR$3) -> 3.805 | AT7: =($U7*$AV$4)+($AF7*$AV$3)+($AS7*$AV$2) -> 21.45 | AU7: =$AT7*2 -> 42.9 | AV7: =IF($AU7>=80,"AI Expert",if($AU7>=60,"AI Practitioner",IF(AND($AU7<60,$AU7>=25),"AI Experimenter",if(and($AU7<25,$AU7>=0),"AI Novice")))) -> AI Experimenter | AW7: ='Raw Data'!Y3 -> CoPilot, ChatGPT | AX7: ='Raw Data'!Z3 -> TRUE | AY7: =#REF! -> #REF! | AZ7: =#REF! -> #REF! | BA7: =#REF! -> #REF! | BB7: =#REF! -> #REF! | BC7: =#REF! -> #REF! | BD7: =#REF! -> #REF! | BE7: =#REF! -> #REF! | BF7: =#REF! -> #REF! | ... BQ7: =#REF! -> #REF! | BR7: ='Raw Data'!C3 -> Staff | BS7: ='Raw Data'!D3 | BT7: ='Raw Data'!E3 -> Information Technology | BU7: ='Raw Data'!F3 -> Directors, People Managers, Supervisors, Team Leads | BV7: ='Raw Data'!G3 | BW7: ='Raw Data'!H3 -> Central Office | BX7: ='Raw Data'!I3 | BY7: ='Raw Data'!J3
